Workbook

Sheet DATA
A1: OrderDate | B1: Region | C1: Rep | D1: Item | E1: Units | F1: UnitCost | G1: Total
A2: 45295 | B2: East | C2: Jones | D2: Binder | E2: 60 | F2: 4.99 | G2: 299.4
A3: 45300 | B3: Central | C3: Smith | D3: Desk | E3: 2 | F3: 125 | G3: 250
A4: 45417 | B4: Central | C4: Jardine | D4: Pencil | E4: 90 | F4: 4.99 | G4: 449.1
A5: 45422 | B5: Central | C5: Morgan | D5: Binder | E5: 28 | F5: 8.99 | G5: 251.72
A6: 45444 | B6: East | C6: Jones | D6: Pencil | E6: 95 | F6: 1.99 | G6: 189.05
A7: 45510 | B7: East | C7: Jones | D7: Binder | E7: 60 | F7: 8.99 | G7: 539.4
A8: 45515 | B8: East | C8: Parent | D8: Pen | E8: 15 | F8: 19.99 | G8: 299.85
A9: 45537 | B9: Central | C9: Jardine | D9: Pencil | E9: 36 | F9: 4.99 | G9: 179.64
A10: 45633 | B10: East | C10: Howard | D10: Binder | E10: 29 | F10: 1.99 | G10: 57.71
A11: 45638 | B11: Central | C11: Smith | D11: Pencil | E11: 67 | F11: 1.29 | G11: 86.43
A12: 45659 | B12: Central | C12: Smith | D12: Binder | E12: 87 | F12: 15 | G12: 1305
A13: 45754 | B13: East | C13: Jones | D13: Pen Set | E13: 62 | F13: 4.99 | G13: 309.38
... A18: 45939 | B18: Central | C18: Gill | D18: Pencil | E18: 7 | F18: 1.29 | G18: 9.03
A19: 1/15/2025 | B19: Central | C19: Gill | D19: Binder | E19: 46 | F19: 8.99 | G19: 413.54
A20: 1/23/2024 | B20: Central | C20: Kivell | D20: Binder | E20: 50 | F20: 19.99 | G20: 999.5
A21: 10/14/2025 | B21: West | C21: Thompson | D21: Binder | E21: 57 | F21: 19.99 | G21: 1139.43
A22: 10/22/2024 | B22: East | C22: Jones | D22: Pen | E22: 64 | F22: 8.99 | G22: 575.36
A23: 10/31/2025 | B23: Central | C23: Andrews | D23: Pencil | E23: 14 | F23: 1.29 | G23: 18.06
A24: 11/17/2025 | B24: Central | C24: Jardine | D24: Binder | E24: 11 | F24: 4.99 | G24: 54.89
A25: 11/25/2024 | B25: Central | C25: Kivell | D25: Pen Set | E25: 96 | F25: 4.99 | G25: 479.04
A26: 12/21/2025 | B26: Central | C26: Andrews | D26: Binder | E26: 28 | F26: 4.99 | G26: 139.72
A27: 12/29/2024 | B27: East | C27: Parent | D27: Pen Set | E27: 74 | F27: 15.99 | G27: 1183.26
A28: 2/18/2025 | B28: East | C28: Jones | D28: Binder | E28: 4 | F28: 4.99 | G28: 19.96
A29: 2/26/2024 | B29: Central | C29: Gill | D29: Pen | E29: 27 | F29: 19.99 | G29: 539.73
A30: 3/15/2024 | B30: West | C30: Sorvino | D30: Pencil | E30: 56 | F30: 2.99 | G30: 167.44
... A44: 9/27/2025 | B44: West | C44: Sorvino | D44: Pen | E44: 76 | F44: 1.99 | G44: 151.24

Sheet Sheet1
A1: OrderDate | B1: Region | C1: Rep | D1: Item | E1: Units | F1: UnitCost | G1: Total
A2: 45759 | B2: Central | C2: Jardine | D2: Binder | E2: 94 | F2: 19.99 | G2: 1879.06 | I2: OPERATION
A3: 7/29/2024 | B3: East | C3: Parent | D3: Binder | E3: 81 | F3: 19.99 | G3: 1619.19
A4: 45659 | B4: Central | C4: Smith | D4: Binder | E4: 87 | F4: 15 | G4: 1305 | I4: Top total sale show red colour
A5: 12/29/2024 | B5: East | C5: Parent | D5: Pen Set | E5: 74 | F5: 15.99 | G5: 1183.26 | I5: Above 10rs unit cost show in green colour cell
A6: 10/14/2025 | B6: West | C6: Thompson | D6: Binder | E6: 57 | F6: 19.99 | G6: 1139.43
A7: 45846 | B7: Central | C7: Kivell | D7: Pen Set | E7: 42 | F7: 23.95 | G7: 1005.9
A8: 1/23/2024 | B8: Central | C8: Kivell | D8: Binder | E8: 50 | F8: 19.99 | G8: 999.5
A9: 8/24/2025 | B9: West | C9: Sorvino | D9: Desk | E9: 3 | F9: 275 | G9: 825
A10: 5/31/2025 | B10: Central | C10: Gill | D10: Binder | E10: 80 | F10: 8.99 | G10: 719.2
A11: 7/21/2025 | B11: Central | C11: Morgan | D11: Pen Set | E11: 55 | F11: 12.49 | G11: 686.95
A12: 6/17/2025 | B12: Central | C12: Kivell | D12: Desk | E12: 5 | F12: 125 | G12: 625
A13: 10/22/2024 | B13: East | C13: Jones | D13: Pen | E13: 64 | F13: 8.99 | G13: 575.36
A14: 2/26/2024 | B14: Central | C14: Gill | D14: Pen | E14: 27 | F14: 19.99 | G14: 539.73
A15: 45510 | B15: East | C15: Jones | D15: Binder | E15: 60 | F15: 8.99 | G15: 539.4
A16: 11/25/2024 | B16: Central | C16: Kivell | D16: Pen Set | E16: 96 | F16: 4.99 | G16: 479.04
A17: 4/27/2025 | B17: East | C17: Howard | D17: Pen | E17: 96 | F17: 4.99 | G17: 479.04
A18: 45417 | B18: Central | C18: Jardine | D18: Pencil | E18: 90 | F18: 4.99 | G18: 449.1
A19: 6/25/2024 | B19: Central | C19: Morgan | D19: Pencil | E19: 90 | F19: 4.99 | G19: 449.1
A20: 1/15/2025 | B20: Central | C20: Gill | D20: Binder | E20: 46 | F20: 8.99 | G20: 413.54
A21: 45754 | B21: East | C21: Jones | D21: Pen Set | E21: 62 | F21: 4.99 | G21: 309.38
A22: 45515 | B22: East | C22: Parent | D22: Pen | E22: 15 | F22: 19.99 | G22: 299.85
A23: 45295 | B23: East | C23: Jones | D23: Binder | E23: 60 | F23: 4.99 | G23: 299.4
A24: 9/18/2024 | B24: East | C24: Jones | D24: Pen Set | E24: 16 | F24: 15.99 | G24: 255.84
A25: 45422 | B25: Central | C25: Morgan | D25: Binder | E25: 28 | F25: 8.99 | G25: 251.72
A26: 45300 | B26: Central | C26: Smith | D26: Desk | E26: 2 | F26: 125 | G26: 250
A27: 3/24/2025 | B27: Central | C27: Jardine | D27: Pen Set | E27: 50 | F27: 4.99 | G27: 249.5
A28: 45444 | B28: East | C28: Jones | D28: Pencil | E28: 95 | F28: 1.99 | G28: 189.05
A29: 45537 | B29: Central | C29: Jardine | D29: Pencil | E29: 36 | F29: 4.99 | G29: 179.64
A30: 8/15/2024 | B30: East | C30: Jones | D30: Pencil | E30: 35 | F30: 4.99 | G30: 174.65
A31: 3/15/2024 | B31: West | C31: Sorvino | D31: Pencil | E31: 56 | F31: 2.99 | G31: 167.44
A32: 9/27/2025 | B32: West | C32: Sorvino | D32: Pen | E32: 76 | F32: 1.99 | G32: 151.24
A33: 4/18/2024 | B33: Central | C33: Andrews | D33: Pencil | E33: 75 | F33: 1.99 | G33: 149.25
A34: 45841 | B34: West | C34: Sorvino | D34: Binder | E34: 7 | F34: 19.99 | G34: 139.93
A35: 12/21/2025 | B35: Central | C35: Andrews | D35: Binder | E35: 28 | F35: 4.99 | G35: 139.72
A36: 45934 | B36: Central | C36: Andrews | D36: Pencil | E36: 66 | F36: 1.99 | G36: 131.34
A37: 45638 | B37: Central | C37: Smith | D37: Pencil | E37: 67 | F37: 1.29 | G37: 86.43
A38: 5/14/2025 | B38: Central | C38: Gill | D38: Pencil | E38: 53 | F38: 1.29 | G38: 68.37
A39: 5/22/2024 | B39: West | C39: Thompson | D39: Pencil | E39: 32 | F39: 1.99 | G39: 63.68
A40: 45633 | B40: East | C40: Howard | D40: Binder | E40: 29 | F40: 1.99 | G40: 57.71
...

Sheet VLOOKUP
B2: vlookup
A7: order date | B7: unit | C7: total profit
A8: 45295 | B8: =VLOOKUP(A8,Table1[[OrderDate]:[Units]],5,FALSE) -> 60 | C8: =VLOOKUP(A8,DATA!A2:G44,7,FALSE) -> 299.4
A9: 45300 | B9: =VLOOKUP(A9,Table1[[OrderDate]:[Units]],5,FALSE) -> 2 | C9: =VLOOKUP(A9,DATA!A3:G45,7,FALSE) -> 250
A10: 45417 | B10: =VLOOKUP(A10,Table1[[OrderDate]:[Units]],5,FALSE) -> 90 | C10: =VLOOKUP(A10,DATA!A4:G46,7,FALSE) -> 449.1
A11: 45422 | B11: =VLOOKUP(A11,Table1[[OrderDate]:[Units]],5,FALSE) -> 28 | C11: =VLOOKUP(A11,DATA!A5:G47,7,FALSE) -> 251.72
A12: 45444 | B12: =VLOOKUP(A12,Table1[[OrderDate]:[Units]],5,FALSE) -> 95 | C12: =VLOOKUP(A12,DATA!A6:G48,7,FALSE) -> 189.05
A13: 45510 | B13: =VLOOKUP(A13,Table1[[OrderDate]:[Units]],5,FALSE) -> 60 | C13: =VLOOKUP(A13,DATA!A7:G49,7,FALSE) -> 539.4
A14: 45515 | B14: =VLOOKUP(A14,Table1[[OrderDate]:[Units]],5,FALSE) -> 15 | C14: =VLOOKUP(A14,DATA!A8:G50,7,FALSE) -> 299.85
A15: 45537 | B15: =VLOOKUP(A15,Table1[[OrderDate]:[Units]],5,FALSE) -> 36 | C15: =VLOOKUP(A15,DATA!A9:G51,7,FALSE) -> 179.64
A16: 45633 | B16: =VLOOKUP(A16,Table1[[OrderDate]:[Units]],5,FALSE) -> 29 | C16: =VLOOKUP(A16,DATA!A10:G52,7,FALSE) -> 57.71
A17: 45638 | B17: =VLOOKUP(A17,Table1[[OrderDate]:[Units]],5,FALSE) -> 67 | C17: =VLOOKUP(A17,DATA!A11:G53,7,FALSE) -> 86.43
A18: 45659 | B18: =VLOOKUP(A18,Table1[[OrderDate]:[Units]],5,FALSE) -> 87 | C18: =VLOOKUP(A18,DATA!A12:G54,7,FALSE) -> 1305
A19: 45754 | B19: =VLOOKUP(A19,Table1[[OrderDate]:[Units]],5,FALSE) -> 62 | C19: =VLOOKUP(A19,DATA!A13:G55,7,FALSE) -> 309.38
... A24: 45939 | B24: =VLOOKUP(A24,Table1[[OrderDate]:[Units]],5,FALSE) -> 7 | C24: =VLOOKUP(A24,DATA!A18:G60,7,FALSE) -> 9.03
A25: 1/15/2025 | B25: =VLOOKUP(A25,Table1[[OrderDate]:[Units]],5,FALSE) -> 46 | C25: =VLOOKUP(A25,DATA!A19:G61,7,FALSE) -> 413.54
A26: 1/23/2024 | B26: =VLOOKUP(A26,Table1[[OrderDate]:[Units]],5,FALSE) -> 50 | C26: =VLOOKUP(A26,DATA!A20:G62,7,FALSE) -> 999.5
A27: 10/14/2025 | B27: =VLOOKUP(A27,Table1[[OrderDate]:[Units]],5,FALSE) -> 57 | C27: =VLOOKUP(A27,DATA!A21:G63,7,FALSE) -> 1139.43
A28: 10/22/2024 | B28: =VLOOKUP(A28,Table1[[OrderDate]:[Units]],5,FALSE) -> 64 | C28: =VLOOKUP(A28,DATA!A22:G64,7,FALSE) -> 575.36
A29: 10/31/2025 | B29: =VLOOKUP(A29,Table1[[OrderDate]:[Units]],5,FALSE) -> 14 | C29: =VLOOKUP(A29,DATA!A23:G65,7,FALSE) -> 18.06
A30: 11/17/2025 | B30: =VLOOKUP(A30,Table1[[OrderDate]:[Units]],5,FALSE) -> 11 | C30: =VLOOKUP(A30,DATA!A24:G66,7,FALSE) -> 54.89
A31: 11/25/2024 | B31: =VLOOKUP(A31,Table1[[OrderDate]:[Units]],5,FALSE) -> 96 | C31: =VLOOKUP(A31,DATA!A25:G67,7,FALSE) -> 479.04
A32: 12/21/2025 | B32: =VLOOKUP(A32,Table1[[OrderDate]:[Units]],5,FALSE) -> 28 | C32: =VLOOKUP(A32,DATA!A26:G68,7,FALSE) -> 139.72
A33: 12/29/2024 | B33: =VLOOKUP(A33,Table1[[OrderDate]:[Units]],5,FALSE) -> 74 | C33: =VLOOKUP(A33,DATA!A27:G69,7,FALSE) -> 1183.26
A34: 2/18/2025 | B34: =VLOOKUP(A34,Table1[[OrderDate]:[Units]],5,FALSE) -> 4 | C34: =VLOOKUP(A34,DATA!A28:G70,7,FALSE) -> 19.96
A35: 2/26/2024 | B35: =VLOOKUP(A35,Table1[[OrderDate]:[Units]],5,FALSE) -> 27 | C35: =VLOOKUP(A35,DATA!A29:G71,7,FALSE) -> 539.73
A36: 3/15/2024 | B36: =VLOOKUP(A36,Table1[[OrderDate]:[Units]],5,FALSE) -> 56 | C36: =VLOOKUP(A36,DATA!A30:G72,7,FALSE) -> 167.44
... A50: 9/27/2025 | B50: =VLOOKUP(A50,Table1[[OrderDate]:[Units]],5,FALSE) -> 76 | C50: =VLOOKUP(A50,DATA!A44:G86,7,FALSE) -> 151.24

Sheet HLOOKUP
D2: HLOOKUP
A4: Order date | B4: 45295 | C4: 45300 | D4: 45417 | E4: 45422 | F4: 45444 | G4: 45510 | H4: 45515 | I4: 45537 | J4: 45633 | K4: 45638 | L4: 45659 | M4: 45754 | N4: 45759 | O4: 45841 | P4: 45846 | Q4: 45934 | R4: 45939 | S4: 1/15/2025 | T4: 1/23/2024 | U4: 10/14/2025 | V4: 10/22/2024 | W4: 10/31/2025 | X4: 11/17/2025 | Y4: 11/25/2024 | Z4: 12/21/2025 | AA4: 12/29/2024 | AB4: 2/18/2025 | AC4: 2/26/2024 | AD4: 3/15/2024 | AE4: 3/24/2025 | AF4: 4/18/2024 | AG4: 4/27/2025 | AH4: 5/14/2025 | AI4: 5/22/2024 | AJ4: 5/31/2025 | AK4: 6/17/2025 | AL4: 6/25/2024 | AM4: 7/21/2025 | AN4: 7/29/2024 | AO4: 8/15/2024 | AP4: 8/24/2025 | AQ4: 9/18/2024 | AR4: 9/27/2025
A5: Unit | B5: 60 | C5: 2 | D5: 90 | E5: 28 | F5: 95 | G5: 60 | H5: 15 | I5: 36 | J5: 29 | K5: 67 | L5: 87 | M5: 62 | N5: 94 | O5: 7 | P5: 42 | Q5: 66 | R5: 7 | S5: 46 | T5: 50 | U5: 57 | V5: 64 | W5: 14 | X5: 11 | Y5: 96 | Z5: 28 | AA5: 74 | AB5: 4 | AC5: 27 | AD5: 56 | AE5: 50 | AF5: 75 | AG5: 96 | AH5: 53 | AI5: 32 | AJ5: 80 | AK5: 5 | AL5: 90 | AM5: 55 | AN5: 81 | AO5: 35 | AP5: 3 | AQ5: 16 | AR5: 76
A6: total sale | B6: 299.4 | C6: 250 | D6: 449.1 | E6: 251.72 | F6: 189.05 | G6: 539.4 | H6: 299.85 | I6: 179.64 | J6: 57.71 | K6: 86.43 | L6: 1305 | M6: 309.38 | N6: 1879.06 | O6: 139.93 | P6: 1005.9 | Q6: 131.34 | R6: 9.03 | S6: 413.54 | T6: 999.5 | U6: 1139.43 | V6: 575.36 | W6: 18.06 | X6: 54.89 | Y6: 479.04 | Z6: 139.72 | AA6: 1183.26 | AB6: 19.96 | AC6: 539.73 | AD6: 167.44 | AE6: 249.5 | AF6: 149.25 | AG6: 479.04 | AH6: 68.37 | AI6: 63.68 | AJ6: 719.2 | AK6: 625 | AL6: 449.1 | AM6: 686.95 | AN6: 1619.19 | AO6: 174.65 | AP6: 825 | AQ6: 255.84 | AR6: 151.24
A10: Order date | B10: 45295 | C10: 45300 | D10: 45417 | E10: 45422 | F10: 45444 | G10: 45510 | H10: 45515 | I10: 45537 | J10: 45633 | K10: 45638 | L10: 45659 | M10: 45754 | N10: 45759 | O10: 45841 | P10: 45846 | Q10: 45934 | R10: 45939 | S10: 1/15/2025 | T10: 1/23/2024 | U10: 10/14/2025 | V10: 10/22/2024 | W10: 10/31/2025 | X10: 11/17/2025 | Y10: 11/25/2024 | Z10: 12/21/2025 | AA10: 12/29/2024 | AB10: 2/18/2025 | AC10: 2/26/2024 | AD10: 3/15/2024 | AE10: 3/24/2025 | AF10: 4/18/2024 | AG10: 4/27/2025 | AH10: 5/14/2025 | AI10: 5/22/2024 | AJ10: 5/31/2025 | AK10: 6/17/2025 | AL10: 6/25/2024 | AM10: 7/21/2025 | AN10: 7/29/2024 | AO10: 8/15/2024 | AP10: 8/24/2025 | AQ10: 9/18/2024 | AR10: 9/27/2025
A11: Total sale | B11: =HLOOKUP(B10,B4:AR6,3) -> 299.4 | C11: =HLOOKUP(C10,C4:AS6,3) -> 250 | D11: =HLOOKUP(D10,D4:AT6,3) -> 449.1 | E11: =HLOOKUP(E10,E4:AU6,3) -> 251.72 | F11: =HLOOKUP(F10,F4:AV6,3) -> 189.05 | G11: =HLOOKUP(G10,G4:AW6,3) -> 539.4 | H11: =HLOOKUP(H10,H4:AX6,3) -> 299.85 | I11: =HLOOKUP(I10,I4:AY6,3) -> 179.64 | ... AR11: =HLOOKUP(AR10,AR4:CH6,3) -> 151.24

Sheet PIVOT TABLE
B2: total sale of atom in region wise
A3: Sum of Total
B4: Binder | C4: Desk | D4: Pen | E4: Pen Set | F4: Pencil | G4: Grand Total
A5: Central | B5: 5762.63 | C5: 875 | D5: 539.73 | E5: 2421.39 | F5: 1540.32 | G5: 11139.07
A6: East | B6: 2535.66 | D6: 1354.25 | E6: 1748.48 | F6: 363.7 | G6: 6002.09
A7: West | B7: 1279.36 | C7: 825 | D7: 151.24 | F7: 231.12 | G7: 2486.72
A8: Grand Total | B8: 9577.65 | C8: 1700 | D8: 2045.22 | E8: 4169.87 | F8: 2135.14 | G8: 19627.88
B10: Pivort chart
